2025-10-05 01:16:10,081 | [31mERROR[0m | app | <module>:38 | Application failed: cannot import name 'init_audit_service' from 'services.audit_service' (D:\Working\2025-telegram-v1\services\audit_service.py)
Traceback (most recent call last):
  File "D:\Working\2025-telegram-v1\main.py", line 34, in <module>
    asyncio.run(main())
    ~~~~~~~~~~~^^^^^^^^
  File "C:\Users\chisme\AppData\Local\Programs\Python\Python313\Lib\asyncio\runners.py", line 195, in run
    return runner.run(main)
           ~~~~~~~~~~^^^^^^
  File "C:\Users\chisme\AppData\Local\Programs\Python\Python313\Lib\asyncio\runners.py", line 118, in run
    return self._loop.run_until_complete(task)
           ~~~~~~~~~~~~~~~~~~~~~~~~~~~~~^^^^^^
  File "C:\Users\chisme\AppData\Local\Programs\Python\Python313\Lib\asyncio\base_events.py", line 725, in run_until_complete
    return future.result()
           ~~~~~~~~~~~~~^^
  File "D:\Working\2025-telegram-v1\main.py", line 28, in main
    await app.initialize()
  File "D:\Working\2025-telegram-v1\core\app_initializer.py", line 56, in initialize
    await self._init_web_server()
  File "D:\Working\2025-telegram-v1\core\app_initializer.py", line 161, in _init_web_server
    from web import create_app
  File "D:\Working\2025-telegram-v1\web\__init__.py", line 3, in <module>
    from .app import create_app
  File "D:\Working\2025-telegram-v1\web\app.py", line 16, in <module>
    from web.routes import register_routes
  File "D:\Working\2025-telegram-v1\web\routes\__init__.py", line 9, in <module>
    from .admin_new_features import admin_new_bp
  File "D:\Working\2025-telegram-v1\web\routes\admin_new_features.py", line 13, in <module>
    from services.audit_service import init_audit_service, get_audit_service
ImportError: cannot import name 'init_audit_service' from 'services.audit_service' (D:\Working\2025-telegram-v1\services\audit_service.py). Did you mean: 'audit_service'?
2025-10-05 01:21:31,880 | [32mINFO[0m | app | <module>:36 | Application stopped by user
2025-10-05 01:24:56,063 | [31mERROR[0m | app | <module>:38 | Application failed: [Errno 10048] error while attempting to bind on address ('127.0.0.1', 5000): [winerror 10048] –æ–±—ã—á–Ω–æ —Ä–∞–∑—Ä–µ—à–∞–µ—Ç—Å—è —Ç–æ–ª—å–∫–æ –æ–¥–Ω–æ –∏—Å–ø–æ–ª—å–∑–æ–≤–∞–Ω–∏–µ –∞–¥—Ä–µ—Å–∞ —Å–æ–∫–µ—Ç–∞ (–ø—Ä–æ—Ç–æ–∫–æ–ª/—Å–µ—Ç–µ–≤–æ–π –∞–¥—Ä–µ—Å/–ø–æ—Ä—Ç)
Traceback (most recent call last):
  File "D:\Working\2025-telegram-v1\main.py", line 34, in <module>
    asyncio.run(main())
    ~~~~~~~~~~~^^^^^^^^
  File "C:\Users\chisme\AppData\Local\Programs\Python\Python313\Lib\asyncio\runners.py", line 195, in run
    return runner.run(main)
           ~~~~~~~~~~^^^^^^
  File "C:\Users\chisme\AppData\Local\Programs\Python\Python313\Lib\asyncio\runners.py", line 118, in run
    return self._loop.run_until_complete(task)
           ~~~~~~~~~~~~~~~~~~~~~~~~~~~~~^^^^^^
  File "C:\Users\chisme\AppData\Local\Programs\Python\Python313\Lib\asyncio\base_events.py", line 725, in run_until_complete
    return future.result()
           ~~~~~~~~~~~~~^^
  File "D:\Working\2025-telegram-v1\main.py", line 28, in main
    await app.initialize()
  File "D:\Working\2025-telegram-v1\core\app_initializer.py", line 56, in initialize
    await self._init_web_server()
  File "D:\Working\2025-telegram-v1\core\app_initializer.py", line 193, in _init_web_server
    await site.start()
  File "C:\Users\chisme\AppData\Local\Programs\Python\Python313\Lib\site-packages\aiohttp\web_runner.py", line 121, in start
    self._server = await loop.create_server(
                   ^^^^^^^^^^^^^^^^^^^^^^^^^
    ...<7 lines>...
    )
    ^
  File "C:\Users\chisme\AppData\Local\Programs\Python\Python313\Lib\asyncio\base_events.py", line 1630, in create_server
    raise OSError(err.errno, msg) from None
OSError: [Errno 10048] error while attempting to bind on address ('127.0.0.1', 5000): [winerror 10048] –æ–±—ã—á–Ω–æ —Ä–∞–∑—Ä–µ—à–∞–µ—Ç—Å—è —Ç–æ–ª—å–∫–æ –æ–¥–Ω–æ –∏—Å–ø–æ–ª—å–∑–æ–≤–∞–Ω–∏–µ –∞–¥—Ä–µ—Å–∞ —Å–æ–∫–µ—Ç–∞ (–ø—Ä–æ—Ç–æ–∫–æ–ª/—Å–µ—Ç–µ–≤–æ–π –∞–¥—Ä–µ—Å/–ø–æ—Ä—Ç)
2025-10-05 01:28:24,417 | [31mERROR[0m | app | <module>:38 | Application failed: [Errno 10048] error while attempting to bind on address ('127.0.0.1', 5000): [winerror 10048] –æ–±—ã—á–Ω–æ —Ä–∞–∑—Ä–µ—à–∞–µ—Ç—Å—è —Ç–æ–ª—å–∫–æ –æ–¥–Ω–æ –∏—Å–ø–æ–ª—å–∑–æ–≤–∞–Ω–∏–µ –∞–¥—Ä–µ—Å–∞ —Å–æ–∫–µ—Ç–∞ (–ø—Ä–æ—Ç–æ–∫–æ–ª/—Å–µ—Ç–µ–≤–æ–π –∞–¥—Ä–µ—Å/–ø–æ—Ä—Ç)
Traceback (most recent call last):
  File "D:\Working\2025-telegram-v1\main.py", line 34, in <module>
    asyncio.run(main())
    ~~~~~~~~~~~^^^^^^^^
  File "C:\Users\chisme\AppData\Local\Programs\Python\Python313\Lib\asyncio\runners.py", line 195, in run
    return runner.run(main)
           ~~~~~~~~~~^^^^^^
  File "C:\Users\chisme\AppData\Local\Programs\Python\Python313\Lib\asyncio\runners.py", line 118, in run
    return self._loop.run_until_complete(task)
           ~~~~~~~~~~~~~~~~~~~~~~~~~~~~~^^^^^^
  File "C:\Users\chisme\AppData\Local\Programs\Python\Python313\Lib\asyncio\base_events.py", line 725, in run_until_complete
    return future.result()
           ~~~~~~~~~~~~~^^
  File "D:\Working\2025-telegram-v1\main.py", line 28, in main
    await app.initialize()
  File "D:\Working\2025-telegram-v1\core\app_initializer.py", line 56, in initialize
    await self._init_web_server()
  File "D:\Working\2025-telegram-v1\core\app_initializer.py", line 193, in _init_web_server
    await site.start()
  File "C:\Users\chisme\AppData\Local\Programs\Python\Python313\Lib\site-packages\aiohttp\web_runner.py", line 121, in start
    self._server = await loop.create_server(
                   ^^^^^^^^^^^^^^^^^^^^^^^^^
    ...<7 lines>...
    )
    ^
  File "C:\Users\chisme\AppData\Local\Programs\Python\Python313\Lib\asyncio\base_events.py", line 1630, in create_server
    raise OSError(err.errno, msg) from None
OSError: [Errno 10048] error while attempting to bind on address ('127.0.0.1', 5000): [winerror 10048] –æ–±—ã—á–Ω–æ —Ä–∞–∑—Ä–µ—à–∞–µ—Ç—Å—è —Ç–æ–ª—å–∫–æ –æ–¥–Ω–æ –∏—Å–ø–æ–ª—å–∑–æ–≤–∞–Ω–∏–µ –∞–¥—Ä–µ—Å–∞ —Å–æ–∫–µ—Ç–∞ (–ø—Ä–æ—Ç–æ–∫–æ–ª/—Å–µ—Ç–µ–≤–æ–π –∞–¥—Ä–µ—Å/–ø–æ—Ä—Ç)
2025-10-05 01:39:52,573 | [32mINFO[0m | app | <module>:36 | Application stopped by user
2025-10-05 01:41:32,585 | [32mINFO[0m | app | <module>:36 | Application stopped by user
2025-10-05 01:51:09,056 | [32mINFO[0m | app | <module>:36 | Application stopped by user
2025-10-05 01:56:05,363 | [32mINFO[0m | app | <module>:36 | Application stopped by user
2025-10-05 01:59:49,136 | [32mINFO[0m | app | <module>:36 | Application stopped by user
2025-10-05 02:06:47,542 | [31mERROR[0m | app | <module>:38 | Application failed: [Errno 10048] error while attempting to bind on address ('127.0.0.1', 5000): [winerror 10048] –æ–±—ã—á–Ω–æ —Ä–∞–∑—Ä–µ—à–∞–µ—Ç—Å—è —Ç–æ–ª—å–∫–æ –æ–¥–Ω–æ –∏—Å–ø–æ–ª—å–∑–æ–≤–∞–Ω–∏–µ –∞–¥—Ä–µ—Å–∞ —Å–æ–∫–µ—Ç–∞ (–ø—Ä–æ—Ç–æ–∫–æ–ª/—Å–µ—Ç–µ–≤–æ–π –∞–¥—Ä–µ—Å/–ø–æ—Ä—Ç)
Traceback (most recent call last):
  File "D:\Working\2025-telegram-v1\main.py", line 34, in <module>
    asyncio.run(main())
    ~~~~~~~~~~~^^^^^^^^
  File "C:\Users\chisme\AppData\Local\Programs\Python\Python313\Lib\asyncio\runners.py", line 195, in run
    return runner.run(main)
           ~~~~~~~~~~^^^^^^
  File "C:\Users\chisme\AppData\Local\Programs\Python\Python313\Lib\asyncio\runners.py", line 118, in run
    return self._loop.run_until_complete(task)
           ~~~~~~~~~~~~~~~~~~~~~~~~~~~~~^^^^^^
  File "C:\Users\chisme\AppData\Local\Programs\Python\Python313\Lib\asyncio\base_events.py", line 725, in run_until_complete
    return future.result()
           ~~~~~~~~~~~~~^^
  File "D:\Working\2025-telegram-v1\main.py", line 28, in main
    await app.initialize()
  File "D:\Working\2025-telegram-v1\core\app_initializer.py", line 56, in initialize
    await self._init_web_server()
  File "D:\Working\2025-telegram-v1\core\app_initializer.py", line 193, in _init_web_server
    await site.start()
  File "C:\Users\chisme\AppData\Local\Programs\Python\Python313\Lib\site-packages\aiohttp\web_runner.py", line 121, in start
    self._server = await loop.create_server(
                   ^^^^^^^^^^^^^^^^^^^^^^^^^
    ...<7 lines>...
    )
    ^
  File "C:\Users\chisme\AppData\Local\Programs\Python\Python313\Lib\asyncio\base_events.py", line 1630, in create_server
    raise OSError(err.errno, msg) from None
OSError: [Errno 10048] error while attempting to bind on address ('127.0.0.1', 5000): [winerror 10048] –æ–±—ã—á–Ω–æ —Ä–∞–∑—Ä–µ—à–∞–µ—Ç—Å—è —Ç–æ–ª—å–∫–æ –æ–¥–Ω–æ –∏—Å–ø–æ–ª—å–∑–æ–≤–∞–Ω–∏–µ –∞–¥—Ä–µ—Å–∞ —Å–æ–∫–µ—Ç–∞ (–ø—Ä–æ—Ç–æ–∫–æ–ª/—Å–µ—Ç–µ–≤–æ–π –∞–¥—Ä–µ—Å/–ø–æ—Ä—Ç)
2025-10-05 02:09:58,494 | [31mERROR[0m | app | <module>:38 | Application failed: [Errno 10048] error while attempting to bind on address ('127.0.0.1', 5000): [winerror 10048] –æ–±—ã—á–Ω–æ —Ä–∞–∑—Ä–µ—à–∞–µ—Ç—Å—è —Ç–æ–ª—å–∫–æ –æ–¥–Ω–æ –∏—Å–ø–æ–ª—å–∑–æ–≤–∞–Ω–∏–µ –∞–¥—Ä–µ—Å–∞ —Å–æ–∫–µ—Ç–∞ (–ø—Ä–æ—Ç–æ–∫–æ–ª/—Å–µ—Ç–µ–≤–æ–π –∞–¥—Ä–µ—Å/–ø–æ—Ä—Ç)
Traceback (most recent call last):
  File "D:\Working\2025-telegram-v1\main.py", line 34, in <module>
    asyncio.run(main())
    ~~~~~~~~~~~^^^^^^^^
  File "C:\Users\chisme\AppData\Local\Programs\Python\Python313\Lib\asyncio\runners.py", line 195, in run
    return runner.run(main)
           ~~~~~~~~~~^^^^^^
  File "C:\Users\chisme\AppData\Local\Programs\Python\Python313\Lib\asyncio\runners.py", line 118, in run
    return self._loop.run_until_complete(task)
           ~~~~~~~~~~~~~~~~~~~~~~~~~~~~~^^^^^^
  File "C:\Users\chisme\AppData\Local\Programs\Python\Python313\Lib\asyncio\base_events.py", line 725, in run_until_complete
    return future.result()
           ~~~~~~~~~~~~~^^
  File "D:\Working\2025-telegram-v1\main.py", line 28, in main
    await app.initialize()
  File "D:\Working\2025-telegram-v1\core\app_initializer.py", line 56, in initialize
    await self._init_web_server()
  File "D:\Working\2025-telegram-v1\core\app_initializer.py", line 193, in _init_web_server
    await site.start()
  File "C:\Users\chisme\AppData\Local\Programs\Python\Python313\Lib\site-packages\aiohttp\web_runner.py", line 121, in start
    self._server = await loop.create_server(
                   ^^^^^^^^^^^^^^^^^^^^^^^^^
    ...<7 lines>...
    )
    ^
  File "C:\Users\chisme\AppData\Local\Programs\Python\Python313\Lib\asyncio\base_events.py", line 1630, in create_server
    raise OSError(err.errno, msg) from None
OSError: [Errno 10048] error while attempting to bind on address ('127.0.0.1', 5000): [winerror 10048] –æ–±—ã—á–Ω–æ —Ä–∞–∑—Ä–µ—à–∞–µ—Ç—Å—è —Ç–æ–ª—å–∫–æ –æ–¥–Ω–æ –∏—Å–ø–æ–ª—å–∑–æ–≤–∞–Ω–∏–µ –∞–¥—Ä–µ—Å–∞ —Å–æ–∫–µ—Ç–∞ (–ø—Ä–æ—Ç–æ–∫–æ–ª/—Å–µ—Ç–µ–≤–æ–π –∞–¥—Ä–µ—Å/–ø–æ—Ä—Ç)
2025-10-05 02:14:54,172 | [32mINFO[0m | app | <module>:36 | Application stopped by user
2025-10-08 18:27:45,786 | [31mERROR[0m | app | <module>:38 | Application failed: [Errno 10048] error while attempting to bind on address ('127.0.0.1', 5000): [winerror 10048] –æ–±—ã—á–Ω–æ —Ä–∞–∑—Ä–µ—à–∞–µ—Ç—Å—è —Ç–æ–ª—å–∫–æ –æ–¥–Ω–æ –∏—Å–ø–æ–ª—å–∑–æ–≤–∞–Ω–∏–µ –∞–¥—Ä–µ—Å–∞ —Å–æ–∫–µ—Ç–∞ (–ø—Ä–æ—Ç–æ–∫–æ–ª/—Å–µ—Ç–µ–≤–æ–π –∞–¥—Ä–µ—Å/–ø–æ—Ä—Ç)
Traceback (most recent call last):
  File "D:\Working\2025-telegram-v1\main.py", line 34, in <module>
    asyncio.run(main())
    ~~~~~~~~~~~^^^^^^^^
  File "C:\Users\chisme\AppData\Local\Programs\Python\Python313\Lib\asyncio\runners.py", line 195, in run
    return runner.run(main)
           ~~~~~~~~~~^^^^^^
  File "C:\Users\chisme\AppData\Local\Programs\Python\Python313\Lib\asyncio\runners.py", line 118, in run
    return self._loop.run_until_complete(task)
           ~~~~~~~~~~~~~~~~~~~~~~~~~~~~~^^^^^^
  File "C:\Users\chisme\AppData\Local\Programs\Python\Python313\Lib\asyncio\base_events.py", line 725, in run_until_complete
    return future.result()
           ~~~~~~~~~~~~~^^
  File "D:\Working\2025-telegram-v1\main.py", line 28, in main
    await app.initialize()
  File "D:\Working\2025-telegram-v1\core\app_initializer.py", line 56, in initialize
    await self._init_web_server()
  File "D:\Working\2025-telegram-v1\core\app_initializer.py", line 193, in _init_web_server
    await site.start()
  File "C:\Users\chisme\AppData\Local\Programs\Python\Python313\Lib\site-packages\aiohttp\web_runner.py", line 121, in start
    self._server = await loop.create_server(
                   ^^^^^^^^^^^^^^^^^^^^^^^^^
    ...<7 lines>...
    )
    ^
  File "C:\Users\chisme\AppData\Local\Programs\Python\Python313\Lib\asyncio\base_events.py", line 1630, in create_server
    raise OSError(err.errno, msg) from None
OSError: [Errno 10048] error while attempting to bind on address ('127.0.0.1', 5000): [winerror 10048] –æ–±—ã—á–Ω–æ —Ä–∞–∑—Ä–µ—à–∞–µ—Ç—Å—è —Ç–æ–ª—å–∫–æ –æ–¥–Ω–æ –∏—Å–ø–æ–ª—å–∑–æ–≤–∞–Ω–∏–µ –∞–¥—Ä–µ—Å–∞ —Å–æ–∫–µ—Ç–∞ (–ø—Ä–æ—Ç–æ–∫–æ–ª/—Å–µ—Ç–µ–≤–æ–π –∞–¥—Ä–µ—Å/–ø–æ—Ä—Ç)
2025-10-13 21:22:40,055 | [32mINFO[0m | app | <module>:36 | Application stopped by user
2025-10-13 21:25:07,847 | [32mINFO[0m | app | <module>:36 | Application stopped by user
2025-10-13 21:27:15,703 | [32mINFO[0m | app | <module>:36 | Application stopped by user
2025-10-14 22:34:51,075 | [32mINFO[0m | app | <module>:36 | Application stopped by user
2025-10-14 22:39:23,645 | [32mINFO[0m | app | <module>:36 | Application stopped by user
2025-10-14 22:48:50,155 | [32mINFO[0m | app | <module>:36 | Application stopped by user
2025-10-14 22:51:55,842 | [32mINFO[0m | app | <module>:36 | Application stopped by user
2025-10-14 22:55:55,415 | [32mINFO[0m | app | <module>:36 | Application stopped by user
2025-10-14 22:57:41,643 | [32mINFO[0m | app | <module>:36 | Application stopped by user
2025-10-14 23:03:14,018 | [32mINFO[0m | app | <module>:36 | Application stopped by user
2025-10-15 17:55:51,145 | [32mINFO[0m | app | <module>:36 | Application stopped by user
2025-10-15 17:59:05,079 | [32mINFO[0m | app | <module>:36 | Application stopped by user
2025-10-15 18:24:00,846 | [31mERROR[0m | app | <module>:38 | Application failed: HTTP Client says - ClientConnectorDNSError: Cannot connect to host api.telegram.org:443 ssl:default [getaddrinfo failed]
Traceback (most recent call last):
  File "C:\Users\chisme\AppData\Local\Programs\Python\Python313\Lib\site-packages\aiohttp\connector.py", line 1532, in _create_direct_connection
    hosts = await self._resolve_host(host, port, traces=traces)
            ^^^^^^^^^^^^^^^^^^^^^^^^^^^^^^^^^^^^^^^^^^^^^^^^^^^
  File "C:\Users\chisme\AppData\Local\Programs\Python\Python313\Lib\site-packages\aiohttp\connector.py", line 1148, in _resolve_host
    return await asyncio.shield(resolved_host_task)
           ^^^^^^^^^^^^^^^^^^^^^^^^^^^^^^^^^^^^^^^^
  File "C:\Users\chisme\AppData\Local\Programs\Python\Python313\Lib\site-packages\aiohttp\connector.py", line 1179, in _resolve_host_with_throttle
    addrs = await self._resolver.resolve(host, port, family=self._family)
            ^^^^^^^^^^^^^^^^^^^^^^^^^^^^^^^^^^^^^^^^^^^^^^^^^^^^^^^^^^^^^
  File "C:\Users\chisme\AppData\Local\Programs\Python\Python313\Lib\site-packages\aiohttp\resolver.py", line 40, in resolve
    infos = await self._loop.getaddrinfo(
            ^^^^^^^^^^^^^^^^^^^^^^^^^^^^^
    ...<5 lines>...
    )
    ^
  File "C:\Users\chisme\AppData\Local\Programs\Python\Python313\Lib\asyncio\base_events.py", line 939, in getaddrinfo
    return await self.run_in_executor(
           ^^^^^^^^^^^^^^^^^^^^^^^^^^^
        None, getaddr_func, host, port, family, type, proto, flags)
        ^^^^^^^^^^^^^^^^^^^^^^^^^^^^^^^^^^^^^^^^^^^^^^^^^^^^^^^^^^^
  File "C:\Users\chisme\AppData\Local\Programs\Python\Python313\Lib\concurrent\futures\thread.py", line 59, in run
    result = self.fn(*self.args, **self.kwargs)
  File "C:\Users\chisme\AppData\Local\Programs\Python\Python313\Lib\socket.py", line 977, in getaddrinfo
    for res in _socket.getaddrinfo(host, port, family, type, proto, flags):
               ~~~~~~~~~~~~~~~~~~~^^^^^^^^^^^^^^^^^^^^^^^^^^^^^^^^^^^^^^^^
socket.gaierror: [Errno 11001] getaddrinfo failed

The above exception was the direct cause of the following exception:

Traceback (most recent call last):
  File "C:\Users\chisme\AppData\Local\Programs\Python\Python313\Lib\site-packages\aiogram\client\session\aiohttp.py", line 177, in make_request
    async with session.post(
               ~~~~~~~~~~~~^
        url, data=form, timeout=self.timeout if timeout is None else timeout
        ^^^^^^^^^^^^^^^^^^^^^^^^^^^^^^^^^^^^^^^^^^^^^^^^^^^^^^^^^^^^^^^^^^^^
    ) as resp:
    ^
  File "C:\Users\chisme\AppData\Local\Programs\Python\Python313\Lib\site-packages\aiohttp\client.py", line 1488, in __aenter__
    self._resp: _RetType = await self._coro
                           ^^^^^^^^^^^^^^^^
  File "C:\Users\chisme\AppData\Local\Programs\Python\Python313\Lib\site-packages\aiohttp\client.py", line 770, in _request
    resp = await handler(req)
           ^^^^^^^^^^^^^^^^^^
  File "C:\Users\chisme\AppData\Local\Programs\Python\Python313\Lib\site-packages\aiohttp\client.py", line 725, in _connect_and_send_request
    conn = await self._connector.connect(
           ^^^^^^^^^^^^^^^^^^^^^^^^^^^^^^
        req, traces=traces, timeout=real_timeout
        ^^^^^^^^^^^^^^^^^^^^^^^^^^^^^^^^^^^^^^^^
    )
    ^
  File "C:\Users\chisme\AppData\Local\Programs\Python\Python313\Lib\site-packages\aiohttp\connector.py", line 642, in connect
    proto = await self._create_connection(req, traces, timeout)
            ^^^^^^^^^^^^^^^^^^^^^^^^^^^^^^^^^^^^^^^^^^^^^^^^^^^
  File "C:\Users\chisme\AppData\Local\Programs\Python\Python313\Lib\site-packages\aiohttp\connector.py", line 1209, in _create_connection
    _, proto = await self._create_direct_connection(req, traces, timeout)
               ^^^^^^^^^^^^^^^^^^^^^^^^^^^^^^^^^^^^^^^^^^^^^^^^^^^^^^^^^^
  File "C:\Users\chisme\AppData\Local\Programs\Python\Python313\Lib\site-packages\aiohttp\connector.py", line 1538, in _create_direct_connection
    raise ClientConnectorDNSError(req.connection_key, exc) from exc
aiohttp.client_exceptions.ClientConnectorDNSError: Cannot connect to host api.telegram.org:443 ssl:default [getaddrinfo failed]

During handling of the above exception, another exception occurred:

Traceback (most recent call last):
  File "D:\Working\2025-telegram-v1\main.py", line 34, in <module>
    asyncio.run(main())
    ~~~~~~~~~~~^^^^^^^^
  File "C:\Users\chisme\AppData\Local\Programs\Python\Python313\Lib\asyncio\runners.py", line 195, in run
    return runner.run(main)
           ~~~~~~~~~~^^^^^^
  File "C:\Users\chisme\AppData\Local\Programs\Python\Python313\Lib\asyncio\runners.py", line 118, in run
    return self._loop.run_until_complete(task)
           ~~~~~~~~~~~~~~~~~~~~~~~~~~~~~^^^^^^
  File "C:\Users\chisme\AppData\Local\Programs\Python\Python313\Lib\asyncio\base_events.py", line 725, in run_until_complete
    return future.result()
           ~~~~~~~~~~~~~^^
  File "D:\Working\2025-telegram-v1\main.py", line 29, in main
    await app.run()
  File "D:\Working\2025-telegram-v1\core\app_initializer.py", line 72, in run
    await bot_task
  File "D:\Working\2025-telegram-v1\bot\optimized_bot.py", line 41, in start
    await self.dispatcher.start_polling(self.bot)
  File "C:\Users\chisme\AppData\Local\Programs\Python\Python313\Lib\site-packages\aiogram\dispatcher\dispatcher.py", line 591, in start_polling
    await asyncio.gather(*done)
  File "C:\Users\chisme\AppData\Local\Programs\Python\Python313\Lib\site-packages\aiogram\dispatcher\dispatcher.py", line 362, in _polling
    user: User = await bot.me()
                 ^^^^^^^^^^^^^^
  File "C:\Users\chisme\AppData\Local\Programs\Python\Python313\Lib\site-packages\aiogram\client\bot.py", line 357, in me
    self._me = await self.get_me()
               ^^^^^^^^^^^^^^^^^^^
  File "C:\Users\chisme\AppData\Local\Programs\Python\Python313\Lib\site-packages\aiogram\client\bot.py", line 1797, in get_me
    return await self(call, request_timeout=request_timeout)
           ^^^^^^^^^^^^^^^^^^^^^^^^^^^^^^^^^^^^^^^^^^^^^^^^^
  File "C:\Users\chisme\AppData\Local\Programs\Python\Python313\Lib\site-packages\aiogram\client\bot.py", line 485, in __call__
    return await self.session(self, method, timeout=request_timeout)
           ^^^^^^^^^^^^^^^^^^^^^^^^^^^^^^^^^^^^^^^^^^^^^^^^^^^^^^^^^
  File "C:\Users\chisme\AppData\Local\Programs\Python\Python313\Lib\site-packages\aiogram\client\session\base.py", line 254, in __call__
    return cast(TelegramType, await middleware(bot, method))
                              ^^^^^^^^^^^^^^^^^^^^^^^^^^^^^
  File "C:\Users\chisme\AppData\Local\Programs\Python\Python313\Lib\site-packages\aiogram\client\session\aiohttp.py", line 184, in make_request
    raise TelegramNetworkError(method=method, message=f"{type(e).__name__}: {e}")
aiogram.exceptions.TelegramNetworkError: HTTP Client says - ClientConnectorDNSError: Cannot connect to host api.telegram.org:443 ssl:default [getaddrinfo failed]
2025-10-15 18:27:28,645 | [32mINFO[0m | app | <module>:36 | Application stopped by user
